Sure, I'd be happy to explain JavaScript async functions to you! Here's an overview of async functions, including basic and advanced examples:

Async functions are a way of writing asynchronous JavaScript code that looks like synchronous code. They use the async keyword to define a function that returns a Promise, and the await keyword to wait for the resolution of a Promise.

Here's a basic example:

javascript

async function foo() {
  const result = await someAsyncOperation();
  return result;
}

In this example, foo() is an async function that awaits the resolution of the Promise returned by someAsyncOperation(). When the Promise resolves, the value it resolves with is stored in the result variable, and then returned by the async function.

Here's a more advanced example that uses Promise.all to run multiple async operations in parallel:

javascript

async function fetchUserData(userId) {
  const [user, posts] = await Promise.all([
    fetch(`https://api.example.com/users/${userId}`),
    fetch(`https://api.example.com/posts?userId=${userId}`)
  ]);
  const userData = {
    user: await user.json(),
    posts: await posts.json()
  };
  return userData;
}

In this example, fetchUserData() is an async function that fetches data from two different URLs using the fetch() function. The Promise.all() method is used to wait for both requests to complete in parallel. The await keyword is used to wait for the resolution of each Promise returned by fetch(), and the .json() method is used to extract the JSON data from each response.

Once both Promises have resolved, the data is combined into a single object and returned by the async function.

Another advanced example is using async functions with error handling using try-catch blocks:

vbnet

async function foo() {
  try {
    const result = await someAsyncOperation();
    return result;
  } catch (error) {
    console.error(error);
    throw new Error('Something went wrong.');
  }
}

In this example, the try block contains the async operation that may throw an error. If an error is thrown, it is caught by the catch block, where it can be logged or handled as needed. In this example, a new Error is thrown with a custom message.

I hope this helps you understand async functions in JavaScript!
