Sure! Here's a comprehensive guide to JavaScript promises, from basic to advanced:
Basic Promise

The simplest form of a Promise is a Promise that resolves after a certain amount of time has passed. Here's an example:

const myPromise = new Promise((resolve, reject) => {
  setTimeout(() => {
    resolve('Success!');
  }, 1000);
});

myPromise.then((result) => {
  console.log(result); // 'Success!'
}).catch((error) => {
  console.error(error);
});

This Promise resolves after 1 second, and logs the string 'Success!' to the console.


Promise with Error Handling

Promises can also reject with an error. Here's an example:

javascript

const myPromise = new Promise((resolve, reject) => {
  setTimeout(() => {
    const error = new Error('Something went wrong');
    reject(error);
  }, 1000);
});

myPromise.then((result) => {
  console.log(result);
}).catch((error) => {
  console.error(error); // 'Error: Something went wrong'
});

This Promise rejects after 1 second with an error, which is then caught and logged to the console.
Chaining Promises

Promises can be chained together, so that the output of one Promise is used as the input for another. Here's an example:

javascript

const promise1 = new Promise((resolve, reject) => {
  setTimeout(() => {
    resolve(1);
  }, 1000);
});

const promise2 = promise1.then((result) => {
  console.log(result); // 1
  return result + 1;
});

const promise3 = promise2.then((result) => {
  console.log(result); // 2
  return result + 1;
});

promise3.then((result) => {
  console.log(result); // 3
});

In this example, promise1 resolves with a value of 1. promise2 is then created, which logs 1 to the console, and returns 2. promise3 is then created, which logs 2 to the console, and returns 3. Finally, promise3 resolves with a value of 3, which is logged to the console.
Promise.all

The Promise.all method can be used to wait for multiple Promises to resolve before continuing. Here's an example:

javascript

const promise1 = new Promise((resolve, reject) => {
  setTimeout(() => {
    resolve(1);
  }, 1000);
});

const promise2 = new Promise((resolve, reject) => {
  setTimeout(() => {
    resolve(2);
  }, 2000);
});

const promise3 = new Promise((resolve, reject) => {
  setTimeout(() => {
    resolve(3);
  }, 3000);
});

Promise.all([promise1, promise2, promise3]).then((results) => {
  console.log(results); // [1
  
  
  
  
  Here's the continuation of the previous answer:

const promise2 = new Promise((resolve, reject) => {
setTimeout(() => {
resolve('Second!');
}, 500);
});

Promise.race([promise1, promise2]).then((result) => {
console.log(result); // 'Second!'
});

vbnet


In this example, `Promise.race` is used to wait for `promise1` and `promise2` to resolve. Since `promise2` resolves first, its value ('Second!') is passed to the `then` method and logged to the console.

## Async/Await

ES2017 introduced a new syntax for working with Promises: `async` and `await`. These keywords allow us to write asynchronous code that looks and behaves like synchronous code. Here's an example:

```javascript
function delay(time) {
  return new Promise((resolve, reject) => {
    setTimeout(() => {
      resolve();
    }, time);
  });
}

async function doSomething() {
  console.log('Doing something...');
  await delay(1000);
  console.log('Done!');
}

doSomething();

In this example, the doSomething function uses the async keyword, which allows it to use the await keyword to pause the execution of the function until the Promise returned by delay has resolved. This results in the console.log('Done!') line being logged to the console 1 second after the console.log('Doing something...') line.



Error Handling with Async/Await

Async/Await also allows us to handle errors using traditional try/catch syntax. Here's an example:

javascript

function fetchUserData(userId) {
  return new Promise((resolve, reject) => {
    if (userId === 1) {
      resolve({ name: 'Alice' });
    } else {
      reject(new Error('User not found'));
    }
  });
}

async function getUserData(userId) {
  try {
    const userData = await fetchUserData(userId);
    console.log(userData.name);
  } catch (error) {
    console.error(error);
  }
}

getUserData(1); // logs 'Alice'
getUserData(2); // logs 'Error: User not found'

In this example, the getUserData function uses async/await to handle errors returned by the fetchUserData function. If the Promise resolves, userData.name is logged to the console. If the Promise rejects, the error is caught and logged to the console.
Promise Decorators

Finally, it's worth mentioning that Promises can be decorated with additional functionality to make them more powerful. Here's an example:

javascript

function retry(promiseFn, maxRetries = 3, delay = 1000) {
  let retries = 0;

  function tryPromise() {
    return promiseFn().catch((error) => {
      if (retries < maxRetries) {
        retries++;
        console.warn(`Retrying after ${delay}ms...`);
        return new Promise((resolve) => setTimeout(resolve, delay)).then(tryPromise);
      }
      throw error;
    });
  }

  return tryPromise();
}

const myPromise = new Promise((resolve, reject) => {
  setTimeout(() => {
    if (Math.random() > 0.5) {
      resolve('Success!');
    } else {
      reject(new Error('Something went wrong'));
    }
  }, 1000);
});

retry(() => myPromise).then((result) => {
  console.log(result);
}).catch((error) => {
  console.error(error);
});


The code defines a retry function that takes in a promiseFn, which is a function that returns a promise, and two optional parameters: maxRetries and delay. The retry function will execute the promiseFn and attempt to resolve the promise. If the promise is rejected due to an error, the retry function will attempt to execute the promise function again, up to maxRetries times, with a delay of delay milliseconds between each retry.

The retry function works by defining an inner function called tryPromise. This function executes the promiseFn and returns a promise. If the promise is resolved successfully, tryPromise will return the resolved value. If the promise is rejected due to an error, tryPromise will check if the number of retries is less than maxRetries. If so, it will increment the retry count and log a message to the console indicating that a retry attempt is being made. It then returns a new promise that resolves after a delay of delay milliseconds and calls tryPromise again recursively.

Finally, the retry function returns the promise returned by tryPromise.

The code then creates a myPromise variable that returns a promise that resolves with the string 'Success!' or rejects with an error after a delay of 1000 milliseconds.

The retry function is then called with myPromise as the promiseFn parameter, causing the retry function to attempt to execute the myPromise function up to 3 times with a delay of 1000 milliseconds between retries. If the myPromise function resolves successfully at any point during these retries, the resolved value will be logged to the console. If the myPromise function is still rejected after the maximum number of retries, the error will be logged to the console.

